<sdf version="1.7">
  <model name="a1_description">
    <link name="base">
      <inertial>
        <pose>0.012728 0.002186 0.000515 0 -0 0</pose>
        <mass>4.714</mass>
        <inertia>
          <ixx>0.0169399</ixx>
          <ixy>8.38742e-05</ixy>
          <ixz>0.000597672</ixz>
          <iyy>0.0565802</iyy>
          <iyz>2.51329e-05</iyz>
          <izz>0.0648138</izz>
        </inertia>
      </inertial>
      <collision name="base_fixed_joint_lump__trunk_collision">
        <pose>0 0 0 0 -0 0</pose>
        <geometry>
          <box>
            <size>0.267 0.194 0.114</size>
          </box>
        </geometry>
      </collision>
      <collision name="base_fixed_joint_lump__imu_link_collision_1">
        <pose>0 0 0 0 -0 0</pose>
        <geometry>
          <box>
            <size>0.001 0.001 0.001</size>
          </box>
        </geometry>
      </collision>
      <visual name="base_visual">
        <pose>0 0 0 0 -0 0</pose>
        <geometry>
          <box>
            <size>0.001 0.001 0.001</size>
          </box>
        </geometry>
      </visual>
      <visual name="base_fixed_joint_lump__trunk_visual_1">
        <pose>0 0 0 0 -0 0</pose>
        <geometry>
          <mesh>
            <scale>1 1 1</scale>
            <uri>model://a1/meshes/trunk.stl</uri>
          </mesh>
        </geometry>
      </visual>
      <visual name="base_fixed_joint_lump__imu_link_visual_2">
        <pose>0 0 0 0 -0 0</pose>
        <geometry>
          <box>
            <size>0.001 0.001 0.001</size>
          </box>
        </geometry>
      </visual>
    </link>
    <joint name="FL_hip_joint" type="revolute">
      <pose relative_to="base">0.183 0.047 0 0 -0 0</pose>
      <parent>base</parent>
      <child>FL_hip</child>
      <axis>
        <xyz>1 0 0</xyz>
        <limit>
          <lower>-0.802851</lower>
          <upper>0.802851</upper>
          <effort>20</effort>
          <velocity>52.4</velocity>
        </limit>
        <dynamics>
          <damping>0</damping>
          <friction>0</friction>
          <spring_reference>0</spring_reference>
          <spring_stiffness>0</spring_stiffness>
        </dynamics>
      </axis>
    </joint>
    <link name="FL_hip">
      <pose relative_to="FL_hip_joint">0 0 0 0 -0 0</pose>
      <inertial>
        <pose>-0.003311 0.000635 3.1e-05 0 -0 0</pose>
        <mass>0.696</mass>
        <inertia>
          <ixx>0.000469246</ixx>
          <ixy>-9.409e-06</ixy>
          <ixz>-3.42e-07</ixz>
          <iyy>0.00080749</iyy>
          <iyz>-4.66e-07</iyz>
          <izz>0.000552929</izz>
        </inertia>
      </inertial>
      <collision name="FL_hip_collision">
        <pose>0 0 0 1.5708 -0 0</pose>
        <geometry>
          <cylinder>
            <length>0.04</length>
            <radius>0.046</radius>
          </cylinder>
        </geometry>
      </collision>
      <visual name="FL_hip_visual">
        <pose>0 0 0 0 -0 0</pose>
        <geometry>
          <mesh>
            <scale>1 1 1</scale>
            <uri>model://a1/meshes/hip.stl</uri>
          </mesh>
        </geometry>
      </visual>
    </link>
    <joint name="FL_thigh_joint" type="revolute">
      <pose relative_to="FL_hip">0 0.08505 0 0 -0 0</pose>
      <parent>FL_hip</parent>
      <child>FL_thigh</child>
      <axis>
        <xyz>0 1 0</xyz>
        <limit>
          <lower>-1.0472</lower>
          <upper>4.18879</upper>
          <effort>55</effort>
          <velocity>28.6</velocity>
        </limit>
        <dynamics>
          <damping>0</damping>
          <friction>0</friction>
          <spring_reference>0</spring_reference>
          <spring_stiffness>0</spring_stiffness>
        </dynamics>
      </axis>
    </joint>
    <link name="FL_thigh">
      <pose relative_to="FL_thigh_joint">0 0 0 0 -0 0</pose>
      <inertial>
        <pose>-0.003237 -0.022327 -0.027326 0 -0 0</pose>
        <mass>1.013</mass>
        <inertia>
          <ixx>0.00552906</ixx>
          <ixy>4.825e-06</ixy>
          <ixz>0.000343869</ixz>
          <iyy>0.00513934</iyy>
          <iyz>2.2448e-05</iyz>
          <izz>0.00136779</izz>
        </inertia>
      </inertial>
      <collision name="FL_thigh_collision">
        <pose>0 0 -0.1 0 1.5708 0</pose>
        <geometry>
          <box>
            <size>0.2 0.0245 0.034</size>
          </box>
        </geometry>
      </collision>
      <visual name="FL_thigh_visual">
        <pose>0 0 0 0 -0 0</pose>
        <geometry>
          <mesh>
            <scale>1 1 1</scale>
            <uri>model://a1/meshes/thigh.stl</uri>
          </mesh>
        </geometry>
      </visual>
    </link>
    <joint name="FL_calf_joint" type="revolute">
      <pose relative_to="FL_thigh">0 0 -0.2 0 -0 0</pose>
      <parent>FL_thigh</parent>
      <child>FL_calf</child>
      <axis>
        <xyz>0 1 0</xyz>
        <limit>
          <lower>-2.69653</lower>
          <upper>-0.916298</upper>
          <effort>55</effort>
          <velocity>28.6</velocity>
        </limit>
        <dynamics>
          <damping>0</damping>
          <friction>0</friction>
          <spring_reference>0</spring_reference>
          <spring_stiffness>0</spring_stiffness>
        </dynamics>
      </axis>
    </joint>
    <link name="FL_calf">
      <pose relative_to="FL_calf_joint">0 0 0 0 -0 0</pose>
      <inertial>
        <pose>0.004727 0 -0.131975 0 -0 0</pose>
        <mass>0.226</mass>
        <inertia>
          <ixx>0.00338557</ixx>
          <ixy>0</ixy>
          <ixz>-0.000167427</ixz>
          <iyy>0.00340344</iyy>
          <iyz>0</iyz>
          <izz>4.38509e-05</izz>
        </inertia>
      </inertial>
      <collision name="FL_calf_collision">
        <pose>0 0 -0.1 0 1.5708 0</pose>
        <geometry>
          <box>
            <size>0.2 0.016 0.016</size>
          </box>
        </geometry>
      </collision>
      <collision name="FL_calf_fixed_joint_lump__FL_foot_collision_1">
        <pose>0 0 -0.2 0 -0 0</pose>
        <geometry>
          <sphere>
            <radius>0.02</radius>
          </sphere>
        </geometry>
      </collision>
      <visual name="FL_calf_visual">
        <pose>0 0 0 0 -0 0</pose>
        <geometry>
          <mesh>
            <scale>1 1 1</scale>
            <uri>model://a1/meshes/calf.stl</uri>
          </mesh>
        </geometry>
      </visual>
      <visual name="FL_calf_fixed_joint_lump__FL_foot_visual_1">
        <pose>0 0 -0.2 0 -0 0</pose>
        <geometry>
          <sphere>
            <radius>0.01</radius>
          </sphere>
        </geometry>
      </visual>
    </link>
    <joint name="FR_hip_joint" type="revolute">
      <pose relative_to="base">0.183 -0.047 0 0 -0 0</pose>
      <parent>base</parent>
      <child>FR_hip</child>
      <axis>
        <xyz>1 0 0</xyz>
        <limit>
          <lower>-0.802851</lower>
          <upper>0.802851</upper>
          <effort>20</effort>
          <velocity>52.4</velocity>
        </limit>
        <dynamics>
          <damping>0</damping>
          <friction>0</friction>
          <spring_reference>0</spring_reference>
          <spring_stiffness>0</spring_stiffness>
        </dynamics>
      </axis>
    </joint>
    <link name="FR_hip">
      <pose relative_to="FR_hip_joint">0 0 0 0 -0 0</pose>
      <inertial>
        <pose>-0.003311 -0.000635 3.1e-05 0 -0 0</pose>
        <mass>0.696</mass>
        <inertia>
          <ixx>0.000469246</ixx>
          <ixy>9.409e-06</ixy>
          <ixz>-3.42e-07</ixz>
          <iyy>0.00080749</iyy>
          <iyz>4.66e-07</iyz>
          <izz>0.000552929</izz>
        </inertia>
      </inertial>
      <collision name="FR_hip_collision">
        <pose>0 0 0 1.5708 -0 0</pose>
        <geometry>
          <cylinder>
            <length>0.04</length>
            <radius>0.046</radius>
          </cylinder>
        </geometry>
      </collision>
      <visual name="FR_hip_visual">
        <pose>0 0 0 -3.14159 0 0</pose>
        <geometry>
          <mesh>
            <scale>1 1 1</scale>
            <uri>model://a1/meshes/hip.stl</uri>
          </mesh>
        </geometry>
      </visual>
    </link>
    <joint name="FR_thigh_joint" type="revolute">
      <pose relative_to="FR_hip">0 -0.08505 0 0 -0 0</pose>
      <parent>FR_hip</parent>
      <child>FR_thigh</child>
      <axis>
        <xyz>0 1 0</xyz>
        <limit>
          <lower>-1.0472</lower>
          <upper>4.18879</upper>
          <effort>55</effort>
          <velocity>28.6</velocity>
        </limit>
        <dynamics>
          <damping>0</damping>
          <friction>0</friction>
          <spring_reference>0</spring_reference>
          <spring_stiffness>0</spring_stiffness>
        </dynamics>
      </axis>
    </joint>
    <link name="FR_thigh">
      <pose relative_to="FR_thigh_joint">0 0 0 0 -0 0</pose>
      <inertial>
        <pose>-0.003237 0.022327 -0.027326 0 -0 0</pose>
        <mass>1.013</mass>
        <inertia>
          <ixx>0.00552906</ixx>
          <ixy>-4.825e-06</ixy>
          <ixz>0.000343869</ixz>
          <iyy>0.00513934</iyy>
          <iyz>-2.2448e-05</iyz>
          <izz>0.00136779</izz>
        </inertia>
      </inertial>
      <collision name="FR_thigh_collision">
        <pose>0 0 -0.1 0 1.5708 0</pose>
        <geometry>
          <box>
            <size>0.2 0.0245 0.034</size>
          </box>
        </geometry>
      </collision>
      <visual name="FR_thigh_visual">
        <pose>0 0 0 0 -0 0</pose>
        <geometry>
          <mesh>
            <scale>1 1 1</scale>
            <uri>model://a1/meshes/thigh_mirror.stl</uri>
          </mesh>
        </geometry>
      </visual>
    </link>
    <joint name="FR_calf_joint" type="revolute">
      <pose relative_to="FR_thigh">0 0 -0.2 0 -0 0</pose>
      <parent>FR_thigh</parent>
      <child>FR_calf</child>
      <axis>
        <xyz>0 1 0</xyz>
        <limit>
          <lower>-2.69653</lower>
          <upper>-0.916298</upper>
          <effort>55</effort>
          <velocity>28.6</velocity>
        </limit>
        <dynamics>
          <damping>0</damping>
          <friction>0</friction>
          <spring_reference>0</spring_reference>
          <spring_stiffness>0</spring_stiffness>
        </dynamics>
      </axis>
    </joint>
    <link name="FR_calf">
      <pose relative_to="FR_calf_joint">0 0 0 0 -0 0</pose>
      <inertial>
        <pose>0.004727 0 -0.131975 0 -0 0</pose>
        <mass>0.226</mass>
        <inertia>
          <ixx>0.00338557</ixx>
          <ixy>0</ixy>
          <ixz>-0.000167427</ixz>
          <iyy>0.00340344</iyy>
          <iyz>0</iyz>
          <izz>4.38509e-05</izz>
        </inertia>
      </inertial>
      <collision name="FR_calf_collision">
        <pose>0 0 -0.1 0 1.5708 0</pose>
        <geometry>
          <box>
            <size>0.2 0.016 0.016</size>
          </box>
        </geometry>
      </collision>
      <collision name="FR_calf_fixed_joint_lump__FR_foot_collision_1">
        <pose>0 0 -0.2 0 -0 0</pose>
        <geometry>
          <sphere>
            <radius>0.02</radius>
          </sphere>
        </geometry>
      </collision>
      <visual name="FR_calf_visual">
        <pose>0 0 0 0 -0 0</pose>
        <geometry>
          <mesh>
            <scale>1 1 1</scale>
            <uri>model://a1/meshes/calf.stl</uri>
          </mesh>
        </geometry>
      </visual>
      <visual name="FR_calf_fixed_joint_lump__FR_foot_visual_1">
        <pose>0 0 -0.2 0 -0 0</pose>
        <geometry>
          <sphere>
            <radius>0.01</radius>
          </sphere>
        </geometry>
      </visual>
    </link>
    <joint name="RL_hip_joint" type="revolute">
      <pose relative_to="base">-0.183 0.047 0 0 -0 0</pose>
      <parent>base</parent>
      <child>RL_hip</child>
      <axis>
        <xyz>1 0 0</xyz>
        <limit>
          <lower>-0.802851</lower>
          <upper>0.802851</upper>
          <effort>20</effort>
          <velocity>52.4</velocity>
        </limit>
        <dynamics>
          <damping>0</damping>
          <friction>0</friction>
          <spring_reference>0</spring_reference>
          <spring_stiffness>0</spring_stiffness>
        </dynamics>
      </axis>
    </joint>
    <link name="RL_hip">
      <pose relative_to="RL_hip_joint">0 0 0 0 -0 0</pose>
      <inertial>
        <pose>0.003311 0.000635 3.1e-05 0 -0 0</pose>
        <mass>0.696</mass>
        <inertia>
          <ixx>0.000469246</ixx>
          <ixy>9.409e-06</ixy>
          <ixz>3.42e-07</ixz>
          <iyy>0.00080749</iyy>
          <iyz>-4.66e-07</iyz>
          <izz>0.000552929</izz>
        </inertia>
      </inertial>
      <collision name="RL_hip_collision">
        <pose>0 0 0 1.5708 -0 0</pose>
        <geometry>
          <cylinder>
            <length>0.04</length>
            <radius>0.046</radius>
          </cylinder>
        </geometry>
      </collision>
      <visual name="RL_hip_visual">
        <pose>0 0 0 3.14159 -0 3.14159</pose>
        <geometry>
          <mesh>
            <scale>1 1 1</scale>
            <uri>model://a1/meshes/hip.stl</uri>
          </mesh>
        </geometry>
      </visual>
    </link>
    <joint name="RL_thigh_joint" type="revolute">
      <pose relative_to="RL_hip">0 0.08505 0 0 -0 0</pose>
      <parent>RL_hip</parent>
      <child>RL_thigh</child>
      <axis>
        <xyz>0 1 0</xyz>
        <limit>
          <lower>-1.0472</lower>
          <upper>4.18879</upper>
          <effort>55</effort>
          <velocity>28.6</velocity>
        </limit>
        <dynamics>
          <damping>0</damping>
          <friction>0</friction>
          <spring_reference>0</spring_reference>
          <spring_stiffness>0</spring_stiffness>
        </dynamics>
      </axis>
    </joint>
    <link name="RL_thigh">
      <pose relative_to="RL_thigh_joint">0 0 0 0 -0 0</pose>
      <inertial>
        <pose>-0.003237 -0.022327 -0.027326 0 -0 0</pose>
        <mass>1.013</mass>
        <inertia>
          <ixx>0.00552906</ixx>
          <ixy>4.825e-06</ixy>
          <ixz>0.000343869</ixz>
          <iyy>0.00513934</iyy>
          <iyz>2.2448e-05</iyz>
          <izz>0.00136779</izz>
        </inertia>
      </inertial>
      <collision name="RL_thigh_collision">
        <pose>0 0 -0.1 0 1.5708 0</pose>
        <geometry>
          <box>
            <size>0.2 0.0245 0.034</size>
          </box>
        </geometry>
      </collision>
      <visual name="RL_thigh_visual">
        <pose>0 0 0 0 -0 0</pose>
        <geometry>
          <mesh>
            <scale>1 1 1</scale>
            <uri>model://a1/meshes/thigh.stl</uri>
          </mesh>
        </geometry>
      </visual>
    </link>
    <joint name="RL_calf_joint" type="revolute">
      <pose relative_to="RL_thigh">0 0 -0.2 0 -0 0</pose>
      <parent>RL_thigh</parent>
      <child>RL_calf</child>
      <axis>
        <xyz>0 1 0</xyz>
        <limit>
          <lower>-2.69653</lower>
          <upper>-0.916298</upper>
          <effort>55</effort>
          <velocity>28.6</velocity>
        </limit>
        <dynamics>
          <damping>0</damping>
          <friction>0</friction>
          <spring_reference>0</spring_reference>
          <spring_stiffness>0</spring_stiffness>
        </dynamics>
      </axis>
    </joint>
    <link name="RL_calf">
      <pose relative_to="RL_calf_joint">0 0 0 0 -0 0</pose>
      <inertial>
        <pose>0.004727 0 -0.131975 0 -0 0</pose>
        <mass>0.226</mass>
        <inertia>
          <ixx>0.00338557</ixx>
          <ixy>0</ixy>
          <ixz>-0.000167427</ixz>
          <iyy>0.00340344</iyy>
          <iyz>0</iyz>
          <izz>4.38509e-05</izz>
        </inertia>
      </inertial>
      <collision name="RL_calf_collision">
        <pose>0 0 -0.1 0 1.5708 0</pose>
        <geometry>
          <box>
            <size>0.2 0.016 0.016</size>
          </box>
        </geometry>
      </collision>
      <collision name="RL_calf_fixed_joint_lump__RL_foot_collision_1">
        <pose>0 0 -0.2 0 -0 0</pose>
        <geometry>
          <sphere>
            <radius>0.02</radius>
          </sphere>
        </geometry>
      </collision>
      <visual name="RL_calf_visual">
        <pose>0 0 0 0 -0 0</pose>
        <geometry>
          <mesh>
            <scale>1 1 1</scale>
            <uri>model://a1/meshes/calf.stl</uri>
          </mesh>
        </geometry>
      </visual>
      <visual name="RL_calf_fixed_joint_lump__RL_foot_visual_1">
        <pose>0 0 -0.2 0 -0 0</pose>
        <geometry>
          <sphere>
            <radius>0.01</radius>
          </sphere>
        </geometry>
      </visual>
    </link>
    <joint name="RR_hip_joint" type="revolute">
      <pose relative_to="base">-0.183 -0.047 0 0 -0 0</pose>
      <parent>base</parent>
      <child>RR_hip</child>
      <axis>
        <xyz>1 0 0</xyz>
        <limit>
          <lower>-0.802851</lower>
          <upper>0.802851</upper>
          <effort>20</effort>
          <velocity>52.4</velocity>
        </limit>
        <dynamics>
          <damping>0</damping>
          <friction>0</friction>
          <spring_reference>0</spring_reference>
          <spring_stiffness>0</spring_stiffness>
        </dynamics>
      </axis>
    </joint>
    <link name="RR_hip">
      <pose relative_to="RR_hip_joint">0 0 0 0 -0 0</pose>
      <inertial>
        <pose>0.003311 -0.000635 3.1e-05 0 -0 0</pose>
        <mass>0.696</mass>
        <inertia>
          <ixx>0.000469246</ixx>
          <ixy>-9.409e-06</ixy>
          <ixz>3.42e-07</ixz>
          <iyy>0.00080749</iyy>
          <iyz>4.66e-07</iyz>
          <izz>0.000552929</izz>
        </inertia>
      </inertial>
      <collision name="RR_hip_collision">
        <pose>0 0 0 1.5708 -0 0</pose>
        <geometry>
          <cylinder>
            <length>0.04</length>
            <radius>0.046</radius>
          </cylinder>
        </geometry>
      </collision>
      <visual name="RR_hip_visual">
        <pose>0 0 0 0 -0 3.14159</pose>
        <geometry>
          <mesh>
            <scale>1 1 1</scale>
            <uri>model://a1/meshes/hip.stl</uri>
          </mesh>
        </geometry>
      </visual>
    </link>
    <joint name="RR_thigh_joint" type="revolute">
      <pose relative_to="RR_hip">0 -0.08505 0 0 -0 0</pose>
      <parent>RR_hip</parent>
      <child>RR_thigh</child>
      <axis>
        <xyz>0 1 0</xyz>
        <limit>
          <lower>-1.0472</lower>
          <upper>4.18879</upper>
          <effort>55</effort>
          <velocity>28.6</velocity>
        </limit>
        <dynamics>
          <damping>0</damping>
          <friction>0</friction>
          <spring_reference>0</spring_reference>
          <spring_stiffness>0</spring_stiffness>
        </dynamics>
      </axis>
    </joint>
    <link name="RR_thigh">
      <pose relative_to="RR_thigh_joint">0 0 0 0 -0 0</pose>
      <inertial>
        <pose>-0.003237 0.022327 -0.027326 0 -0 0</pose>
        <mass>1.013</mass>
        <inertia>
          <ixx>0.00552906</ixx>
          <ixy>-4.825e-06</ixy>
          <ixz>0.000343869</ixz>
          <iyy>0.00513934</iyy>
          <iyz>-2.2448e-05</iyz>
          <izz>0.00136779</izz>
        </inertia>
      </inertial>
      <collision name="RR_thigh_collision">
        <pose>0 0 -0.1 0 1.5708 0</pose>
        <geometry>
          <box>
            <size>0.2 0.0245 0.034</size>
          </box>
        </geometry>
      </collision>
      <visual name="RR_thigh_visual">
        <pose>0 0 0 0 -0 0</pose>
        <geometry>
          <mesh>
            <scale>1 1 1</scale>
            <uri>model://a1/meshes/thigh_mirror.stl</uri>
          </mesh>
        </geometry>
      </visual>
    </link>
    <joint name="RR_calf_joint" type="revolute">
      <pose relative_to="RR_thigh">0 0 -0.2 0 -0 0</pose>
      <parent>RR_thigh</parent>
      <child>RR_calf</child>
      <axis>
        <xyz>0 1 0</xyz>
        <limit>
          <lower>-2.69653</lower>
          <upper>-0.916298</upper>
          <effort>55</effort>
          <velocity>28.6</velocity>
        </limit>
        <dynamics>
          <damping>0</damping>
          <friction>0</friction>
          <spring_reference>0</spring_reference>
          <spring_stiffness>0</spring_stiffness>
        </dynamics>
      </axis>
    </joint>
    <link name="RR_calf">
      <pose relative_to="RR_calf_joint">0 0 0 0 -0 0</pose>
      <inertial>
        <pose>0.004727 0 -0.131975 0 -0 0</pose>
        <mass>0.226</mass>
        <inertia>
          <ixx>0.00338557</ixx>
          <ixy>0</ixy>
          <ixz>-0.000167427</ixz>
          <iyy>0.00340344</iyy>
          <iyz>0</iyz>
          <izz>4.38509e-05</izz>
        </inertia>
      </inertial>
      <collision name="RR_calf_collision">
        <pose>0 0 -0.1 0 1.5708 0</pose>
        <geometry>
          <box>
            <size>0.2 0.016 0.016</size>
          </box>
        </geometry>
      </collision>
      <collision name="RR_calf_fixed_joint_lump__RR_foot_collision_1">
        <pose>0 0 -0.2 0 -0 0</pose>
        <geometry>
          <sphere>
            <radius>0.02</radius>
          </sphere>
        </geometry>
      </collision>
      <visual name="RR_calf_visual">
        <pose>0 0 0 0 -0 0</pose>
        <geometry>
          <mesh>
            <scale>1 1 1</scale>
            <uri>model://a1/meshes/calf.stl</uri>
          </mesh>
        </geometry>
      </visual>
      <visual name="RR_calf_fixed_joint_lump__RR_foot_visual_1">
        <pose>0 0 -0.2 0 -0 0</pose>
        <geometry>
          <sphere>
            <radius>0.01</radius>
          </sphere>
        </geometry>
      </visual>
    </link>
  </model>
</sdf>